Workbook
Name _\A: #REF!
Name _\q: #REF!
Name _\x: #REF!
Name __\A: #REF!
Name __\q: #REF!
Name __\x: #REF!
Name ___\A: #REF!
Name ___\q: #REF!
Name ____\A: #REF!
Name ____\q: #REF!
Name _____\A: #REF!
Name _____\q: #REF!
Name ______\A: #REF!
Name ______\q: #REF!
Name _______\A: #REF!
Name _______\q: #REF!
Name ___jum1: #REF!
Name ___jum1: #REF!
Name ___jum10: #REF!
Name ___jum10: #REF!
Name ___jum2: #REF!
Name ___jum2: #REF!
Name ___jum3: #REF!
Name ___jum3: #REF!
Name ___jum4: #REF!
Name ___jum4: #REF!
Name ___jum5: #REF!
Name ___jum5: #REF!
Name ___jum6: #REF!
Name ___jum6: #REF!
Name ___jum7: #REF!
Name ___jum7: #REF!
Name ___jum8: #REF!
Name ___jum8: #REF!
Name ___jum9: #REF!
Name ___jum9: #REF!
Name __1A: #REF!
Name __1A: #REF!
Name __jum1: #REF!
Name __jum1: #REF!
Name __jum10: #REF!
Name __jum10: #REF!
Name __jum2: #REF!
Name __jum2: #REF!
Name __jum3: #REF!
Name __jum3: #REF!
Name __jum4: #REF!
Name __jum4: #REF!
Name __jum5: #REF!
Name __jum5: #REF!
Name __jum6: #REF!
Name __jum6: #REF!
Name __jum7: #REF!
Name __jum7: #REF!
Name __jum8: #REF!
Name __jum8: #REF!
Name __jum9: #REF!
Name __jum9: #REF!
Name _1A: #REF!
Name _1A: #REF!

Sheet COVER
A9: S
C10: PROYEK PENGEMBANGAN GENERAL REPAIR & BODY REPAIR DAIHATSU
C11: BATAM- KEPULAUAN RIAU
C39: MINGGU KE -3
C40: PERIODE : 19- 27 April 2026

Sheet REKAP TOTAL
B1: REKAPITULASI PEK. STRUKTUR ARSITEKTUR, MEKANIKAL ELEKTRIKAL | E1: PROGRESS MINGGUAN
B2: PROYEK SHOWROOM & WORKSHOP
B3: DAIHATSU Cabang BATAM-KEPULAUAN RIAU
B4: PT. ASTRA INTERNATIONAL Tbk
B5: PERIODE : 6- 18 April2026
B6: MINGGU KE 2 (Dua)
B9: No. | C9: URAIAN PEKERJAAN | E9: TOTAL HARGA | F9: SUB TOTAL | G9: Bobot | I9: Progres Minggu lalu | L9: Progres Minggu ini | O9: S/D Progres Minggu ini | Q9: Ket.
E10: ( Rp. ) | H10: Volume | I10: Progres (%) | J10: Bobot | K10: Volume | L10: Progres (%) | M10: Bobot | N10: Volume | O10: Progres (%) | P10: Bobot
B12: I | D12: ='I. PERSIAPAN'!D13 -> PEKERJAAN PERSIAPAN | F12: ='I. PERSIAPAN'!I13 -> 1.2302705e+09 | G12: =F12/F44 -> 0.10118113 | I12: =+J12*G12 -> 0.0012159631 | J12: =+'I. PERSIAPAN'!M38 -> 0.012017687 | L12: =+M12*G12 -> 0.00018451542 | M12: =+'I. PERSIAPAN'!P38 -> 0.0018236149 | O12: =+P12*G12 -> 0.0014004785 | P12: =+'I. PERSIAPAN'!S38 -> 0.013841302
B14: II | D14: ='II.PEK. LUAR'!D11 -> PEKERJAAN LUAR | F14: =SUM(E14:E20) -> 1.6429951e+09 | G14: =F14/F44 -> 0.13512483
C15: ='II.PEK. LUAR'!C13 -> A | D15: ='II.PEK. LUAR'!D13 -> PEKERJAAN BONGKARAN | E15: ='II.PEK. LUAR'!I13 -> 99063135 | G15: =E15/F44 -> 0.0081472485 | I15: =+J15*G15 -> 0 | J15: =+'II.PEK. LUAR'!M13 -> 0 | L15: =+M15*G15 -> 0 | M15: =+'I. PERSIAPAN'!P41 -> 0 | O15: =+P15*G15 -> 0 | P15: =+'I. PERSIAPAN'!S41 -> 0
C16: ='II.PEK. LUAR'!C14 -> B | D16: ='II.PEK. LUAR'!D14 -> PEKERJAAN SALURAN | E16: ='II.PEK. LUAR'!I14 -> 2.7474589e+08 | G16: =E16/F44 -> 0.022595923 | I16: =+J16*G16 -> 0 | J16: =+'II.PEK. LUAR'!M14 -> 0 | L16: =+M16*G16 -> 0 | M16: =+'I. PERSIAPAN'!P42 -> 0 | O16: =+P16*G16 -> 0 | P16: =+'I. PERSIAPAN'!S42 -> 0
C17: C | D17: ='II.PEK. LUAR'!D15 -> PEKERJAAN PAVING BLOCK, EX. LOKAL / SNI | E17: ='II.PEK. LUAR'!I15 -> 773081348 | G17: =E17/F44 -> 0.063580522 | I17: =+J17*G17 -> 0 | J17: =+'II.PEK. LUAR'!M15 -> 0 | L17: =+M17*G17 -> 0 | M17: =+'I. PERSIAPAN'!P43 -> 0 | O17: =+P17*G17 -> 0 | P17: =+'I. PERSIAPAN'!S43 -> 0
C18: D | D18: ='II.PEK. LUAR'!D16 -> PEKERJAAN LAIN-LAIN | E18: ='II.PEK. LUAR'!I16 -> 64413739 | G18: =E18/F44 -> 0.0052975785 | I18: =+J18*G18 -> 0 | J18: =+'II.PEK. LUAR'!M16 -> 0 | L18: =+M18*G18 -> 0 | M18: =+'I. PERSIAPAN'!P44 -> 0 | O18: =+P18*G18 -> 0 | P18: =+'I. PERSIAPAN'!S44 -> 0
C19: E | D19: PEKERJAAN MEKANIKAL | E19: ='REKAP ME'!C11 -> 2.0200201e+08 | G19: =E19/F44 -> 0.01661325 | I19: =+J19*G19 -> 0 | J19: =+'I. Mek. Infrastruktur'!K59 -> 0 | L19: =+M19*G19 -> 0 | M19: =+'I. PERSIAPAN'!P45 -> 0 | O19: =+P19*G19 -> 0 | P19: =+'I. PERSIAPAN'!S45 -> 0
C20: F | D20: PEKERJAAN ELEKTRIKAL | E20: ='REKAP ME'!C12 -> 2.2968894e+08 | G20: =E20/F44 -> 0.018890305 | I20: =+J20*G20 -> 0 | J20: =+'I. Elektrikal Infrastruktur'!K43 -> 0 | L20: =+M20*G20 -> 0 | M20: =+'I. PERSIAPAN'!P46 -> 0 | O20: =+P20*G20 -> 0 | P20: =+'I. PERSIAPAN'!S46 -> 0
B22: III | D22: PEKERJAAN BANGUNAN BODY REPAIR | F22: =SUM(E23:E28) -> 8.6730794e+09 | G22: =F22/F44 -> 0.71329998
C23: A | D23: PEKERJAAN STRUKTUR | E23: ='III.BODY REPAIR'!H25 -> 6.1240575e+09 | G23: =E23/F44 -> 0.5036608 | I23: =+J23*G23 -> 0 | J23: =+'I. PERSIAPAN'!M49 -> 0 | L23: =+M23*G23 -> 0 | M23: =+'I. PERSIAPAN'!P49 -> 0 | O23: =+P23*G23 -> 0 | P23: =+'I. PERSIAPAN'!S49 -> 0
C24: B | D24: PEKERJAAN ARSITEKTUR | E24: ='III.BODY REPAIR'!H39 -> 1.6782927e+09 | G24: =E24/F44 -> 0.13802781 | I24: =+J24*G24 -> 0 | J24: =+'I. PERSIAPAN'!M50 -> 0 | L24: =+M24*G24 -> 0 | M24: =+'I. PERSIAPAN'!P50 -> 0 | O24: =+P24*G24 -> 0 | P24: =+'I. PERSIAPAN'!S50 -> 0
C25: C | D25: PEKERJAAN MEKANIKAL | E25: ='REKAP ME'!C15 -> 3.8085344e+08 | G25: =E25/F44 -> 0.031322526 | I25: =+J25*G25 -> 0 | J25: =+'I. PERSIAPAN'!M51 -> 0 | L25: =+M25*G25 -> 0 | M25: =+'I. PERSIAPAN'!P51 -> 0 | O25: =+P25*G25 -> 0 | P25: =+'I. PERSIAPAN'!S51 -> 0
C26: D | D26: PEKERJAAN ELEKTRIKAL | E26: ='REKAP ME'!C16 -> 4.6950555e+08 | G26: =E26/F44 -> 0.03861354 | I26: =+J26*G26 -> 0 | J26: =+'I. PERSIAPAN'!M52 -> 0 | L26: =+M26*G26 -> 0 | M26: =+'I. PERSIAPAN'!P52 -> 0 | O26: =+P26*G26 -> 0 | P26: =+'I. PERSIAPAN'!S52 -> 0
C27: E | D27: PEKERJAAN ELEKTRONIK | E27: ='REKAP ME'!C17 -> 20370217 | G27: =E27/F44 -> 0.0016753076 | I27: =+J27*G27 -> 0 | J27: =+'I. PERSIAPAN'!M53 -> 0 | L27: =+M27*G27 -> 0 | M27: =+'I. PERSIAPAN'!P53 -> 0 | O27: =+P27*G27 -> 0 | P27: =+'I. PERSIAPAN'!S53 -> 0
B29: IV | D29: ='IV.GENERAL REPAIR'!E11 -> PEKERJAAN BANGUNAN GENERAL REPAIR | F29: =SUM(E29:E34) -> 4.2007629e+08 | G29: =F29/F44 -> 0.03454833
C30: A | D30: PEKERJAAN STRUKTUR | E30: ='IV.GENERAL REPAIR'!J19 -> 92303864 | G30: =E30/F44 -> 0.0075913458 | I30: =+J30*G30 -> 0 | J30: =+'I. PERSIAPAN'!M56 -> 0 | L30: =+M30*G30 -> 0 | M30: =+'I. PERSIAPAN'!P56 -> 0 | O30: =+P30*G30 -> 0 | P30: =+'I. PERSIAPAN'!S56 -> 0
C31: B | D31: PEKERJAAN ARSITEKTUR | E31: ='IV.GENERAL REPAIR'!J34 -> 2.6329055e+08 | G31: =E31/F44 -> 0.021653802 | I31: =+J31*G31 -> 0 | J31: =+'I. PERSIAPAN'!M57 -> 0 | L31: =+M31*G31 -> 0 | M31: =+'I. PERSIAPAN'!P57 -> 0 | O31: =+P31*G31 -> 0 | P31: =+'I. PERSIAPAN'!S57 -> 0
C32: C | D32: PEKERJAAN MEKANIKAL | E32: ='REKAP ME'!C20 -> 27712542 | G32: =E32/F44 -> 0.0022791624 | I32: =+J32*G32 -> 0 | J32: =+'I. PERSIAPAN'!M58 -> 0 | L32: =+M32*G32 -> 0 | M32: =+'I. PERSIAPAN'!P58 -> 0 | O32: =+P32*G32 -> 0 | P32: =+'I. PERSIAPAN'!S58 -> 0
C33: D | D33: PEKERJAAN ELEKTRIKAL | E33: ='REKAP ME'!C21 -> 36769336 | G33: =E33/F44 -> 0.0030240201 | I33: =+J33*G33 -> 0 | J33: =+'I. PERSIAPAN'!M59 -> 0 | L33: =+M33*G33 -> 0 | M33: =+'I. PERSIAPAN'!P59 -> 0 | O33: =+P33*G33 -> 0 | P33: =+'I. PERSIAPAN'!S59 -> 0
B35: V | D35: ='V.OFFICE & SHOWROOM'!E11 -> PEKERJAAN BANGUNAN OFFICE & SHOWROOM | F35: =SUM(E36:E37) -> 1.487523e+08 | G35: =F35/F44 -> 0.012233834
C36: A | D36: PEKERJAAN ARSITEKTUR | E36: ='V.OFFICE & SHOWROOM'!J25 -> 1.3530789e+08 | G36: =E36/F53 -> 0.09196798 | I36: =+J36*G36 -> 0 | J36: =+'I. PERSIAPAN'!M62 -> 0 | L36: =+M36*G36 -> 0 | M36: =+'I. PERSIAPAN'!P62 -> 0 | O36: =+P36*G36 -> 0 | P36: =+'I. PERSIAPAN'!S62 -> 0
C37: B | D37: PEKERJAAN ELEKTRIKAL | E37: ='REKAP ME'!C24 -> 13444408 | G37: =E37/F44 -> 0.0011057083 | I37: =+J37*G37 -> 0 | J37: =+'I. PERSIAPAN'!M63 -> 0 | L37: =+M37*G37 -> 0 | M37: =+'I. PERSIAPAN'!P63 -> 0 | O37: =+P37*G37 -> 0 | P37: =+'I. PERSIAPAN'!S63 -> 0
B39: VI | D39: ='VI.KONDISI EXISTING'!D11 -> PEKERJAAN KONDISI EXISTING | F39: =SUM(E40:E41) -> 43917400 | G39: =F39/F44 -> 0.0036118983
C40: A | D40: PEKERJAAN PEMBONGKARAN DAN PERBAIKAN | E40: ='VI.KONDISI EXISTING'!I18 -> 43917400 | G40: =E40/F44 -> 0.0036118983 | I40: =+J40*G40 -> 0 | J40: =+'I. PERSIAPAN'!M66 -> 0 | L40: =+M40*G40 -> 0 | M40: =+'I. PERSIAPAN'!P66 -> 0 | O40: =+P40*G40 -> 0 | P40: =+'I. PERSIAPAN'!S66 -> 0
B42: Total Pekerjaan | G42: =G12+G14+G22+G29+G35+G39 -> 1 | I42: =SUM(I12:I40) -> 0.0012159631 | J42: =SUM(J12:J41) -> 0.012017687 | L42: =SUM(L12:L41) -> 0.00018451542 | M42: =SUM(M12:M41) -> 0.0018236149 | O42: =SUM(O12:O41) -> 0.0014004785 | P42: =SUM(P12:P41) -> 0.013841302
D44: SUB TOTAL 1 | F44: =SUM(F12:F42) -> 1.2159091e+10
D46: PROFIT & OVERHEAD KONTRAKTOR | E46: 0.1 | F46: =F44*E46 -> 1.2159091e+09
D49: SUB TOTAL 2 | F49: =SUM(F44:F47) -> 1.3375e+10
D51: DIBULATKAN | F51: =ROUNDDOWN(F49,-6) -> 13375000000
D53: PPN | E53: 0.11 | F53: =E53*F51 -> 1471250000
D56: GRAND TOTAL | F56: =SUM(F51:F53) -> 14846250000
Q60: Batam ,27 April 2026
...

Sheet I. PERSIAPAN
B1: PROGRESS MINGGUAN
B2: PROYEK SHOWROOM & WORKSHOP
B3: DAIHATSU Cabang BATAM-KEPULAUAN RIAU
B4: PT. ASTRA INTERNATIONAL Tbk
B5: PERIODE : 6- 18 April2026
B6: MINGGU KE 2 (Dua)
B8: NO | D8: URAIAN PEKERJAAN | E8: SAT | F8: VOLUME | G8: VOLUME KONTRAKTOR | H8: HARGA SAT | I8: JUMLAH HARGA | J8: Bobot | K8: Progres s/d Minggu Lalu | N8: Progres Minggu ini | Q8: Progres s/d Minggu ini | T8: Ket. | W8: Perhitungan volume di kolom ini
H9: ( Rp. ) | I9: ( Rp. ) | K9: Volume | L9: Progres (%) | M9: Bobot | N9: Volume | O9: Progres (%) | P9: Bobot | Q9: Volume | R9: Progres (%) | S9: Bobot
D11: REKAPITULASI
B13: I | D13: PEKERJAAN PERSIAPAN | I13: =$I$38 -> 1.2302705e+09 | J13: =I13/'REKAP TOTAL'!F44 -> 0.10118113
B16: I | D16: PEKERJAAN PERSIAPAN
B18: 1 | D18: Proyek Manajemen dan biaya - biaya administrasi lapangan | E18: ls | F18: 1 | G18: 1 | H18: 225000000 | I18: =$G18*H18 -> 225000000 | J18: =I18/'REKAP TOTAL'!F44 -> 0.018504673 | K18: 0.5 | L18: 0.5 | M18: 0.0092523364 | N18: =+Q18-K18 -> 0 | O18: =+R18-L18 -> 0 | P18: =+S18-M18 -> 0 | Q18: =+W18 -> 0.5 | R18: =+Q18/F18 -> 0.5 | S18: =+R18*J18 -> 0.0092523364 | W18: 0.5
D19: ( Staf kontraktor di site harus ada personil Safety Officer dan Quality Control )
B20: 2 | D20: Mobilisasi dan demobilisasi tenaga kerja dan peralatan, termasuk alat pancang, Alat bor, Scafolding dll | E20: ls | F20: 1 | G20: 1 | H20: 587645000 | I20: =$G20*H20 -> 587645000 | J20: =I20/'REKAP TOTAL'!F44 -> 0.048329682 | K20: 0 | L20: 0 | M20: 0 | N20: =+Q20-K20 -> 0 | O20: =+R20-L20 -> 0 | P20: =+S20-M20 -> 0 | Q20: =+W20 -> 0 | R20: =+Q20/F20 -> 0 | S20: =+R20*J20 -> 0 | W20: 0
B21: =B20+1 -> 3 | D21: Penjagaan dan perawatan jalan, pagar, trotoar yang ada | E21: ls | F21: 1 | G21: 1 | H21: 5000000 | I21: =$G21*H21 -> 5000000 | J21: =I21/'REKAP TOTAL'!F44 -> 0.00041121495 | K21: 0 | L21: 0 | M21: 0 | N21: =+Q21-K21 -> 0 | O21: =+R21-L21 -> 0 | P21: =+S21-M21 -> 0 | Q21: =+W21 -> 0 | R21: =+Q21/F21 -> 0 | S21: =+R21*J21 -> 0 | W21: 0
B22: =B21+1 -> 4 | D22: Keamanan lapangan selama pekerjaan berlangsung | E22: ls | F22: 1 | G22: 1 | H22: 35000000 | I22: =$G22*H22 -> 35000000 | J22: =I22/'REKAP TOTAL'!F44 -> 0.0028785047 | K22: 0.05 | L22: 0.05 | M22: 0.00014392523 | N22: =+Q22-K22 -> 0.05 | O22: =+R22-L22 -> 0.05 | P22: =+S22-M22 -> 0.00014392523 | Q22: =+W22 -> 0.1 | R22: =+Q22/F22 -> 0.1 | S22: =+R22*J22 -> 0.00028785047 | W22: 0.1
B23: =B22+1 -> 5 | D23: Sumber air kerja (dengan jet pump) berikut peralatan penunjang | E23: ls | F23: 1 | G23: 1 | H23: 15870000 | I23: =$G23*H23 -> 15870000 | J23: =I23/'REKAP TOTAL'!F44 -> 0.0013051963 | K23: 0 | L23: 0 | M23: 0 | N23: =+Q23-K23 -> 0.05 | O23: =+R23-L23 -> 0.05 | P23: =+S23-M23 -> 6.5259813e-05 | Q23: =+W23 -> 0.05 | R23: =+Q23/F23 -> 0.05 | S23: =+R23*J23 -> 6.5259813e-05 | W23: 0.05
B24: =B23+1 -> 6 | D24: Pengadaan sumber listrik kerja (dengan genset) berikut peralatan penunjang | E24: ls | F24: 1 | G24: 1 | H24: 69700000 | I24: =$G24*H24 -> 69700000 | J24: =I24/'REKAP TOTAL'!F44 -> 0.0057323364 | K24: 0 | L24: 0 | M24: 0 | N24: =+Q24-K24 -> 0.1 | O24: =+R24-L24 -> 0.1 | P24: =+S24-M24 -> 0.00057323364 | Q24: =+W24 -> 0.1 | R24: =+Q24/F24 -> 0.1 | S24: =+R24*J24 -> 0.00057323364 | W24: 0.1
B25: =B24+1 -> 7 | D25: Peralatan komunikasi (telepon, HT, dll) | E25: ls | F25: 1 | G25: 1 | H25: 10800000 | I25: =$G25*H25 -> 10800000 | J25: =I25/'REKAP TOTAL'!F44 -> 0.0008882243 | K25: 0 | L25: 0 | M25: 0 | N25: =+Q25-K25 -> 0 | O25: =+R25-L25 -> 0 | P25: =+S25-M25 -> 0 | Q25: =+W25 -> 0 | R25: =+Q25/F25 -> 0 | S25: =+R25*J25 -> 0 | W25: 0
B26: =B25+1 -> 8 | D26: Asuransi ( C.A.R, ASTEK dan Personal Incident 3 person ) | E26: ls | F26: 1 | G26: 1 | H26: 38300000 | I26: =$G26*H26 -> 38300000 | J26: =I26/'REKAP TOTAL'!F44 -> 0.0031499065 | K26: 0 | L26: 0 | M26: 0 | N26: =+Q26-K26 -> 0.2 | O26: =+R26-L26 -> 0.2 | P26: =+S26-M26 -> 0.00062998131 | Q26: =+W26 -> 0.2 | R26: =+Q26/F26 -> 0.2 | S26: =+R26*J26 -> 0.00062998131 | W26: 0.2
B27: =B26+1 -> 9 | D27: Pembuatan gambar kerja (shop drawing) & gambar terlaksana ( as built drawing ) | E27: ls | F27: 1 | G27: 1 | H27: 3200000 | I27: =$G27*H27 -> 3200000 | J27: =I27/'REKAP TOTAL'!F44 -> 0.00026317757 | K27: 0.05 | L27: 0.05 | M27: 1.3158878e-05 | N27: =+Q27-K27 -> 0 | O27: =+R27-L27 -> 0 | P27: =+S27-M27 -> 0 | Q27: =+W27 -> 0.05 | R27: =+Q27/F27 -> 0.05 | S27: =+R27*J27 -> 1.3158878e-05 | W27: 0.05
B28: 10 | D28: Peralatan Pengaman dan APD (sepatu boot, helm, fire extinguiser , dsb) | E28: ls | F28: 1 | G28: 1 | H28: 7400000 | I28: =$G28*H28 -> 7400000 | J28: =I28/'REKAP TOTAL'!F44 -> 0.00060859813 | K28: 0.1 | L28: 0.1 | M28: 6.0859813e-05 | N28: =+Q28-K28 -> 0 | O28: =+R28-L28 -> 0 | P28: =+S28-M28 -> 0 | Q28: =+W28 -> 0.1 | R28: =+Q28/F28 -> 0.1 | S28: =+R28*J28 -> 6.0859813e-05 | W28: 0.1
B29: =B28+1 -> 11 | D29: Testing material | E29: ls | F29: 1 | G29: 1 | H29: 20000000 | I29: =$G29*H29 -> 20000000 | J29: =I29/'REKAP TOTAL'!F44 -> 0.0016448598 | K29: 0 | L29: 0 | M29: 0 | N29: =+Q29-K29 -> 0 | O29: =+R29-L29 -> 0 | P29: =+S29-M29 -> 0 | Q29: =+W29 -> 0 | R29: =+Q29/F29 -> 0 | S29: =+R29*J29 -> 0 | W29: 0
B30: =B29+1 -> 12 | D30: Laporan Progres pekerjaan dilengkapi dengan dokumen photo, setiap minggu | E30: ls | F30: 1 | G30: 1 | H30: 3000000 | I30: =$G30*H30 -> 3000000 | J30: =I30/'REKAP TOTAL'!F44 -> 0.00024672897 | K30: 0.01 | L30: 0.01 | M30: 2.4672897e-06 | N30: =+Q30-K30 -> 0 | O30: =+R30-L30 -> 0 | P30: =+S30-M30 -> 0 | Q30: =+W30 -> 0.01 | R30: =+Q30/F30 -> 0.01 | S30: =+R30*J30 -> 2.4672897e-06 | W30: =+F30*0.01 -> 0.01
B31: =B30+1 -> 13 | D31: Pekerjaan Pengukuran yang diperlukan selama proyek berlangsung | E31: ls | F31: 1 | G31: 1 | H31: 4500000 | I31: =$G31*H31 -> 4500000 | J31: =I31/'REKAP TOTAL'!F44 -> 0.00037009346 | K31: 0.05 | L31: 0.05 | M31: 1.8504673e-05 | N31: =+Q31-K31 -> 0 | O31: =+R31-L31 -> 0 | P31: =+S31-M31 -> 0 | Q31: =+W31 -> 0.05 | R31: =+Q31/F31 -> 0.05 | S31: =+R31*J31 -> 1.8504673e-05 | W31: 0.05
B32: =B31+1 -> 14 | D32: Koordinasi Lingkungan dan Perijinan yang berkaitan dengan pelaksanaan diluar IMB | E32: ls | F32: 1 | G32: 1 | H32: 100000000 | I32: =$G32*H32 -> 100000000 | J32: =I32/'REKAP TOTAL'!F44 -> 0.008224299 | K32: 0 | L32: 0 | M32: 0 | N32: =+Q32-K32 -> 0.05 | O32: =+R32-L32 -> 0.05 | P32: =+S32-M32 -> 0.00041121495 | Q32: =+W32 -> 0.05 | R32: =+Q32/F32 -> 0.05 | S32: =+R32*J32 -> 0.00041121495 | W32: =+F32*0.05 -> 0.05
B33: =B32+1 -> 15 | D33: Kantor dan Gudang kontraktor sementara dan Los kerja , sesuai kebutuhan | E33: ls | F33: 1 | G33: 1 | H33: 31600000 | I33: =$G33*H33 -> 31600000 | J33: =I33/'REKAP TOTAL'!F44 -> 0.0025988785 | K33: 0.5 | L33: 0.5 | M33: 0.0012994392 | N33: =+Q33-K33 -> 0 | O33: =+R33-L33 -> 0 | P33: =+S33-M33 -> -1.9515639e-18 | Q33: =+W33 -> 0.5 | R33: =+Q33/F33 -> 0.5 | S33: =+R33*J33 -> 0.0012994392 | W33: =+F33*0.5 -> 0.5
B34: =B33+1 -> 16 | D34: Buangan material bongkaran keluar lokasi | E34: ls | F34: 1 | G34: 1 | H34: 5000000 | I34: =$G34*H34 -> 5000000 | J34: =I34/'REKAP TOTAL'!F44 -> 0.00041121495 | K34: 0 | L34: 0 | M34: 0 | N34: =+Q34-K34 -> 0 | O34: =+R34-L34 -> 0 | P34: =+S34-M34 -> 0 | Q34: =+W34 -> 0 | R34: =+Q34/F34 -> 0 | S34: =+R34*J34 -> 0 | W34: 0
B35: 17 | D35: Pagar sementara seng H=2,4 m fin oil paint + rangka + pintu gerbang selama konstruksi pentahapan area bengkel | E35: m' | F35: =107+17.202 -> 124.202 | G35: 124.202 | H35: 300300 | I35: =$G35*H35 -> 37297861 | J35: =I35/'REKAP TOTAL'!F44 -> 0.0030674876 | K35: 49.6808 | L35: 0.4 | M35: 0.001226995 | N35: =+Q35-K35 -> 0 | O35: =+R35-L35 -> 0 | P35: =+S35-M35 -> 3.9031278e-18 | Q35: =+W35 -> 49.6808 | R35: =+Q35/F35 -> 0.4 | S35: =+R35*J35 -> 0.001226995 | W35: =+F35*0.4 -> 49.6808
B36: 18 | D36: Jembatan temporary utk akses mobilisasi alat berat | E36: ls | F36: 1 | G36: 1 | H36: 30957665 | I36: =$G36*H36 -> 30957665 | J36: =I36/'REKAP TOTAL'!F44 -> 0.0025460509 | K36: 0 | L36: 0 | M36: 0 | N36: =+Q36-K36 -> 0 | O36: =+R36-L36 -> 0 | P36: =+S36-M36 -> 0 | Q36: =+W36 -> 0 | R36: =+Q36/F36 -> 0 | S36: =+R36*J36 -> 0 | W36: 0
D38: Total Pekerjaan Persiapan … | I38: =SUM(I17:I37) -> 1.2302705e+09 | J38: =I38/'REKAP TOTAL'!F44 -> 0.10118113 | M38: =SUM(M18:M37) -> 0.012017687 | P38: =SUM(P18:P37) -> 0.0018236149 | S38: =SUM(S18:S37) -> 0.013841302
D45: u

Sheet II.PEK. LUAR
B1: ='I. PERSIAPAN'!B1 -> PROGRESS MINGGUAN
B2: ='I. PERSIAPAN'!B2 -> PROYEK SHOWROOM & WORKSHOP
B3: ='I. PERSIAPAN'!B3 -> DAIHATSU Cabang BATAM-KEPULAUAN RIAU
B4: ='I. PERSIAPAN'!B4 -> PT. ASTRA INTERNATIONAL Tbk
B5: ='I. PERSIAPAN'!B5 -> PERIODE : 6- 18 April2026
B6: ='I. PERSIAPAN'!B6 -> MINGGU KE 2 (Dua)
B8: No | C8: URAIAN PEKERJAAN | E8: SAT | F8: VOLUME | G8: VOLUME KONTRAKTOR | H8: HARGA SAT ( Rp ) | I8: JUMLAH ( Rp ) | J8: Bobot | K8: Progres s/d Minggu Lalu | N8: Progres Minggu ini | Q8: Progres s/d Minggu ini | T8: Ket.
K9: Volume | L9: Progres (%) | M9: Bobot | N9: Volume | O9: Progres (%) | P9: Bobot | Q9: Volume | R9: Progres (%) | S9: Bobot
B11: II | D11: PEKERJAAN LUAR
C13: A | D13: =D18 -> PEKERJAAN BONGKARAN | I13: =$I$45 -> 99063135 | J13: =I13/'REKAP TOTAL'!F44 -> 0.0081472485
C14: B | D14: =D46 -> PEKERJAAN SALURAN | I14: =$I$56 -> 2.7474589e+08 | J14: =I14/'REKAP TOTAL'!F44 -> 0.022595923
C15: C | D15: =D58 -> PEKERJAAN PAVING BLOCK, EX. LOKAL / SNI | I15: =$I$68 -> 773081348 | J15: =I15/'REKAP TOTAL'!F44 -> 0.063580522
C16: D | D16: =D70 -> PEKERJAAN LAIN-LAIN | I16: =$I$87 -> 64413739 | J16: =I16/'REKAP TOTAL'!F44 -> 0.0052975785
J17: =SUM(J13:J16) -> 0.099621272
B18: A | D18: PEKERJAAN BONGKARAN
B20: 1 | D20: Area lantai basement (General repair)
D21: * R. Part Ex. Repair & samping stall 5 : Pekerjaan pembongkaran dinding, termasuk pintu | E21: m2 | F21: 76.6077 | G21: 76.6077 | H21: 130400 | I21: =$G21*H21 -> 9989644.1 | J21: =I21/'REKAP TOTAL'!F44 -> 0.0008215782 | K21: 0 | L21: 0 | M21: 0 | N21: =+Q21-K21 -> 0 | O21: =+R21-L21 -> 0 | P21: =+S21-M21 -> 0 | Q21: =+W21 -> 0 | R21: =+Q21/F21 -> 0 | S21: =+R21*J21 -> 0
D22: * R. Part Ex. Repair & R. G. part : Pekerjaan bobokan lantai existing | E22: m2 | F22: 58.46 | G22: 58.46 | H22: 172000 | I22: =$G22*H22 -> 10055120 | J22: =I22/'REKAP TOTAL'!F44 -> 0.00082696314 | K22: 0 | L22: 0 | M22: 0 | N22: =+Q22-K22 -> 0 | O22: =+R22-L22 -> 0 | P22: =+S22-M22 -> 0 | Q22: =+W22 -> 0 | R22: =+Q22/F22 -> 0 | S22: =+R22*J22 -> 0
D23: * Urinal / toilet mekanik : Pekerjaan bobokan dinding keramik existing | E23: m2 | F23: 28.6 | G23: 28.6 | H23: 101300 | I23: =$G23*H23 -> 2897180 | J23: =I23/'REKAP TOTAL'!F44 -> 0.00023827275 | K23: 0 | L23: 0 | M23: 0 | N23: =+Q23-K23 -> 0 | O23: =+R23-L23 -> 0 | P23: =+S23-M23 -> 0 | Q23: =+W23 -> 0 | R23: =+Q23/F23 -> 0 | S23: =+R23*J23 -> 0
D24: * Pekerjaan pembongkaran plafond, untuk :
D25: - R. Part Ex. Repair & R. G. part | E25: m2 | F25: 58.46 | G25: 58.46 | H25: 95300 | I25: =$G25*H25 -> 5571238 | J25: =I25/'REKAP TOTAL'!F44 -> 0.00045819527 | K25: 0 | L25: 0 | M25: 0 | N25: =+Q25-K25 -> 0 | O25: =+R25-L25 -> 0 | P25: =+S25-M25 -> 0 | Q25: =+W25 -> 0 | R25: =+Q25/F25 -> 0 | S25: =+R25*J25 -> 0
D26: - Urinal / toilet mekanik | E26: m2 | F26: 7.256 | G26: 7.256 | H26: 95300 | I26: =$G26*H26 -> 691496.8 | J26: =I26/'REKAP TOTAL'!F44 -> 5.6870765e-05 | K26: 0 | L26: 0 | M26: 0 | N26: =+Q26-K26 -> 0 | O26: =+R26-L26 -> 0 | P26: =+S26-M26 -> 0 | Q26: =+W26 -> 0 | R26: =+Q26/F26 -> 0 | S26: =+R26*J26 -> 0
D27: - R. part exclaim menjadi R. karu | E27: m2 | F27: 10 | G27: 10 | H27: 95300 | I27: =$G27*H27 -> 953000 | J27: =I27/'REKAP TOTAL'!F44 -> 7.837757e-05 | K27: 0 | L27: 0 | M27: 0 | N27: =+Q27-K27 -> 0 | O27: =+R27-L27 -> 0 | P27: =+S27-M27 -> 0 | Q27: =+W27 -> 0 | R27: =+Q27/F27 -> 0 | S27: =+R27*J27 -> 0
D28: - Smoking area menjadi R. security | E28: m2 | F28: 13.45 | G28: 13.45 | H28: 95300 | I28: =$G28*H28 -> 1281785 | J28: =I28/'REKAP TOTAL'!F44 -> 0.00010541783 | K28: 0 | L28: 0 | M28: 0 | N28: =+Q28-K28 -> 0 | O28: =+R28-L28 -> 0 | P28: =+S28-M28 -> 0 | Q28: =+W28 -> 0 | R28: =+Q28/F28 -> 0 | S28: =+R28*J28 -> 0
D29: * Area wastafel & r. part exclaim : Pekerjaan pembongkaran dinding tengah | E29: m2 | F29: 13.7436 | G29: 13.7436 | H29: 130400 | I29: =$G29*H29 -> 1792165.4 | J29: =I29/'REKAP TOTAL'!F44 -> 0.00014739305 | K29: 0 | L29: 0 | M29: 0 | N29: =+Q29-K29 -> 0 | O29: =+R29-L29 -> 0 | P29: =+S29-M29 -> 0 | Q29: =+W29 -> 0 | R29: =+Q29/F29 -> 0 | S29: =+R29*J29 -> 0
D30: * Pekerjaan bobokan lantai existing termasuk keramik, grating / item yang terkait didalamnya, untuk : | G30: 0 | H30: 0
D31: * Combiboot menjadi Stall loading / unloading | E31: m2 | F31: 34.633 | G31: 34.633 | H31: 172000 | I31: =$G31*H31 -> 5956876 | J31: =I31/'REKAP TOTAL'!F44 -> 0.0004899113 | K31: 0 | L31: 0 | M31: 0 | N31: =+Q31-K31 -> 0 | O31: =+R31-L31 -> 0 | P31: =+S31-M31 -> 0 | Q31: =+W31 -> 0 | R31: =+Q31/F31 -> 0 | S31: =+R31*J31 -> 0
D32: * R. security menjadi r. part exclaim | E32: m2 | F32: 7.935 | G32: 7.935 | H32: 172000 | I32: =$G32*H32 -> 1364820 | J32: =I32/'REKAP TOTAL'!F44 -> 0.00011224688 | K32: 0 | L32: 0 | M32: 0 | N32: =+Q32-K32 -> 0 | O32: =+R32-L32 -> 0 | P32: =+S32-M32 -> 0 | Q32: =+W32 -> 0 | R32: =+Q32/F32 -> 0 | S32: =+R32*J32 -> 0
D33: * Area urinal / toilet mekanik, wastafel dan r. part exclaim menjadi urinal & r. karu | E33: m2 | F33: 17.1 | G33: 17.1 | H33: 172000 | I33: =$G33*H33 -> 2941200 | J33: =I33/'REKAP TOTAL'!F44 -> 0.00024189308 | K33: 0 | L33: 0 | M33: 0 | N33: =+Q33-K33 -> 0 | O33: =+R33-L33 -> 0 | P33: =+S33-M33 -> 0 | Q33: =+W33 -> 0 | R33: =+Q33/F33 -> 0 | S33: =+R33*J33 -> 0
D34: * R. smoking area menjadi R. security | E34: m2 | F34: 9.85 | G34: 9.85 | H34: 172000 | I34: =$G34*H34 -> 1694200 | J34: =I34/'REKAP TOTAL'!F44 -> 0.00013933607 | K34: 0 | L34: 0 | M34: 0 | N34: =+Q34-K34 -> 0 | O34: =+R34-L34 -> 0 | P34: =+S34-M34 -> 0 | Q34: =+W34 -> 0 | R34: =+Q34/F34 -> 0 | S34: =+R34*J34 -> 0
D35: * R. g.part & r. gudang bahan : Pekerjaan pembongkaran dinding roster | E35: m2 | F35: 9.4068 | G35: 9.4068 | H35: 191300 | I35: =$G35*H35 -> 1799520.8 | J35: =I35/'REKAP TOTAL'!F44 -> 0.00014799798 | K35: 0 | L35: 0 | M35: 0 | N35: =+Q35-K35 -> 0 | O35: =+R35-L35 -> 0 | P35: =+S35-M35 -> 0 | Q35: =+W35 -> 0 | R35: =+Q35/F35 -> 0 | S35: =+R35*J35 -> 0
D36: * Area stalll dempul, epoxy, masking : Pekerjaan pembongkaran seluruh lantai termasuk grating / item yang terkait didalamnya | E36: m2 | F36: 73.82 | G36: 73.82 | H36: 103600 | I36: =$G36*H36 -> 7647752 | J36: =I36/'REKAP TOTAL'!F44 -> 0.00062897399 | K36: 0 | L36: 0 | M36: 0 | N36: =+Q36-K36 -> 0 | O36: =+R36-L36 -> 0 | P36: =+S36-M36 -> 0 | Q36: =+W36 -> 0 | R36: =+Q36/F36 -> 0 | S36: =+R36*J36 -> 0
B37: 2 | D37: Area lantai 1 (office & showroom)
D38: * R. admin : Pekerjaan pembongkaran dinding partisi , termasuk pintu | E38: m2 | F38: 30.342 | G38: 30.342 | H38: 112900 | I38: =$G38*H38 -> 3425611.8 | J38: =I38/'REKAP TOTAL'!F44 -> 0.00028173256 | K38: 0 | L38: 0 | M38: 0 | N38: =+Q38-K38 -> 0 | O38: =+R38-L38 -> 0 | P38: =+S38-M38 -> 0 | Q38: =+W38 -> 0 | R38: =+Q38/F38 -> 0 | S38: =+R38*J38 -> 0
D39: * R. admin : Pekerjaan pembongkaran plafond | E39: m2 | F39: 28 | G39: 28 | H39: 95300 | I39: =$G39*H39 -> 2668400 | J39: =I39/'REKAP TOTAL'!F44 -> 0.0002194572 | K39: 0 | L39: 0 | M39: 0 | N39: =+Q39-K39 -> 0 | O39: =+R39-L39 -> 0 | P39: =+S39-M39 -> 0 | Q39: =+W39 -> 0 | R39: =+Q39/F39 -> 0 | S39: =+R39*J39 -> 0
B40: 3 | D40: Area lantai 2 (office & showroom)
D41: * R. MPR menjadi r. salesman : Pekerjaan pembongkaran dinding & pintu, termasuk modifikasi railing tangga menjadi dinding bata | E41: m2 | F41: 37.5804 | G41: 37.5804 | H41: 250000 | I41: =$G41*H41 -> 9395100 | J41: =I41/'REKAP TOTAL'!F44 -> 0.00077268112 | K41: 0 | L41: 0 | M41: 0 | N41: =+Q41-K41 -> 0 | O41: =+R41-L41 -> 0 | P41: =+S41-M41 -> 0 | Q41: =+W41 -> 0 | R41: =+Q41/F41 -> 0 | S41: =+R41*J41 -> 0
D42: * R. MPR menjadi r. salesman : Pekerjaan pembongkaran plafond | E42: m2 | F42: 77.05 | G42: 77.05 | H42: 95300 | I42: =$G42*H42 -> 7342865 | J42: =I42/'REKAP TOTAL'!F44 -> 0.00060389918 | K42: 0 | L42: 0 | M42: 0 | N42: =+Q42-K42 -> 0 | O42: =+R42-L42 -> 0 | P42: =+S42-M42 -> 0 | Q42: =+W42 -> 0 | R42: =+Q42/F42 -> 0 | S42: =+R42*J42 -> 0
B43: 4 | D43: Pekerjaan pembongkaran atap, kolom, dinding partisi dan policarbonate beserta rangka pada area washing stall | E43: ls | F43: 1 | G43: 1 | H43: 3405800 | I43: =$G43*H43 -> 3405800 | J43: =I43/'REKAP TOTAL'!F44 -> 0.00028010318 | K43: 0 | L43: 0 | M43: 0 | N43: =+Q43-K43 -> 0 | O43: =+R43-L43 -> 0 | P43: =+S43-M43 -> 0 | Q43: =+W43 -> 0 | R43: =+Q43/F43 -> 0 | S43: =+R43*J43 -> 0
B44: 5 | D44: Metode pemasukan alat pancang dengan HSPD 120 ton bisa melalui jalur / jalan belakang namun ada Pekerjaan bongkar & pemasangan kembali pagar panel ( 3 panel, panjang 1 panel : 2,4 m) di area belakang (melalui tanah stock yard) | E44: m' | F44: 7.2 | G44: 7.2 | H44: 2526300 | I44: =$G44*H44 -> 18189360 | J44: =I44/'REKAP TOTAL'!F44 -> 0.0014959474 | K44: 0 | L44: 0 | M44: 0 | N44: =+Q44-K44 -> 0 | O44: =+R44-L44 -> 0 | P44: =+S44-M44 -> 0 | Q44: =+W44 -> 0 | R44: =+Q44/F44 -> 0 | S44: =+R44*J44 -> 0
...

Sheet III.BODY REPAIR
B1: ='I. PERSIAPAN'!B1 -> PROGRESS MINGGUAN
B2: ='I. PERSIAPAN'!B2 -> PROYEK SHOWROOM & WORKSHOP
B3: ='I. PERSIAPAN'!B3 -> DAIHATSU Cabang BATAM-KEPULAUAN RIAU
B4: ='I. PERSIAPAN'!B4 -> PT. ASTRA INTERNATIONAL Tbk
B5: ='I. PERSIAPAN'!B5 -> PERIODE : 6- 18 April2026
B6: ='I. PERSIAPAN'!B6 -> MINGGU KE 2 (Dua)
B8: NO | C8: URAIAN PEKERJAAN | D8: SAT | E8: VOLUME | F8: VOLUME | G8: VOLUME | H8: VOLUME | I8: Bobot | J8: Progres s/d Minggu Lalu | M8: Progres Minggu ini | P8: Progres s/d Minggu ini | S8: Ket.
G9: ( Rp. ) | H9: ( Rp. ) | J9: Volume | K9: Progres (%) | L9: Bobot | M9: Volume | N9: Progres (%) | O9: Bobot | P9: Volume | Q9: Progres (%) | R9: Bobot
B11: III | C11: PEKERJAAN BANGUNAN BODY REPAIR
B13: 1 | C13: PEKERJAAN STRUKTUR
B15: A | C15: =C45 -> PEKERJAAN PONDASI TIANG PANCANG | H15: =$H$52 -> 553985000 | I15: =H15/'REKAP TOTAL'!F44 -> 0.045561383
B16: B | C16: =C54 -> PEKERJAAN GALIAN DAN URUGAN | H16: =$H$75 -> 7.8155965e+08 | I16: =H16/'REKAP TOTAL'!F44 -> 0.064277803
B17: C | C17: =C77 -> PEKERJAAN LANTAI KERJA | H17: =$H$83 -> 9049333.7 | I17: =H17/'REKAP TOTAL'!F44 -> 0.00074424426
B18: D | C18: =C85 -> PEKERJAAN BETON BERTULANG (K - 300/Fc 25Mpa) | H18: =$H$103 -> 6.5323714e+08 | I18: =H18/'REKAP TOTAL'!F44 -> 0.053724175
B19: E | C19: PEKERJAAN BEKISTING | H19: =$H$115 -> 1.5274648e+08 | I19: =H19/'REKAP TOTAL'!F44 -> 0.012562328
B20: F | C20: PEKERJAAN PEMBESIAN / TULANGAN | H20: =$H$135 -> 6.5450837e+08 | I20: =H20/'REKAP TOTAL'!F44 -> 0.053828725
B21: G | C21: PEKERJAAN KONSTRUKSI BAJA | H21: =$H$190 -> 2.3372353e+09 | I21: =H21/'REKAP TOTAL'!F44 -> 0.19222122
B22: H | C22: PEKERJAAN ATAP | H22: =$H$214 -> 9.6452758e+08 | I22: =H22/'REKAP TOTAL'!F44 -> 0.079325632
B23: I | C23: PEKERJAAN WATERPROOFING | H23: =$H$222 -> 17208684 | I23: =H23/'REKAP TOTAL'!F44 -> 0.0014152936
C25: JUMLAH PEKERJAAN STRUKTUR | H25: =SUM(H15:H23) -> 6.1240575e+09 | I25: =H25/'REKAP TOTAL'!F44 -> 0.5036608
B27: =B224 -> 1 | C27: PEKERJAAN ARSITEKTUR
B29: =B226 -> A | C29: =C226 -> PEKERJAAN PASANGAN BATU BATA & PLESTERAN | H29: =$H$234 -> 1.7460929e+08 | I29: =H29/'REKAP TOTAL'!F44 -> 0.01436039
B30: =B236 -> B | C30: =C236 -> PEKERJAAN LANTAI | H30: =$H$251 -> 8.0897946e+08 | I30: =H30/'REKAP TOTAL'!F44 -> 0.06653289
B31: =B253 -> C | C31: =C253 -> PEKERJAAN FINISHING DINDING | H31: =$H$264 -> 1.601153e+08 | I31: =H31/'REKAP TOTAL'!F44 -> 0.013168361
B32: D | C32: =C266 -> PEKERJAAN KOSEN, PINTU & JENDELA | H32: =$H$340 -> 355230400 | I32: =H32/'REKAP TOTAL'!F44 -> 0.02921521
B33: E | C33: =C342 -> PEKERJAAN PLAFOND | H33: =$H$353 -> 14815820 | I33: =H33/'REKAP TOTAL'!F44 -> 0.0012184973
B34: F | C34: =C355 -> PEKERJAAN PENGECATAN | H34: =$H$370 -> 21129473 | I34: =H34/'REKAP TOTAL'!F44 -> 0.001737751
B35: G | C35: =C372 -> PEKERJAAN SANITAIR | H35: =$H$382 -> 33348200 | I35: =H35/'REKAP TOTAL'!F44 -> 0.0027426557
B36: H | C36: =C384 -> PEKERJAAN LAIN-LAIN | H36: =$H$396 -> 1.1006473e+08 | I36: =H36/'REKAP TOTAL'!F44 -> 0.0090520527
C39: JUMLAH PEKERJAAN ARSITEKTUR | H39: =SUM(H29:H38) -> 1.6782927e+09 | I39: =H39/'REKAP TOTAL'!F44 -> 0.13802781
B43: 1 | C43: PEKERJAAN STRUKTUR
B45: A | C45: PEKERJAAN PONDASI TIANG PANCANG
B47: 1 | C47: Tiang Pancang uk. 25x25 cm L= 15 M dari tanah existing (termasuk Biaya Pemancangan dng hydraulic Jacking dan penyambungan), Mutu beton Fc' = 42 Mpa | D47: m' | E47: 750 | F47: 750 | G47: 612100 | H47: =$F47*G47 -> 459075000 | I47: =H47/'REKAP TOTAL'!F44 -> 0.037755701 | J47: 0 | K47: 0 | L47: 0 | M47: =+P47-J47 -> 25 | N47: =+Q47-K47 -> 0.033333333 | O47: =+R47-L47 -> 0.0012585234 | P47: =+W47 -> 25 | Q47: =+P47/E47 -> 0.033333333 | R47: =+Q47*I47 -> 0.0012585234 | W47: 25
B48: 2 | C48: Pemotongan Kepala Tiang Pancang | D48: ttk | E48: 50 | F48: 50 | G48: 98900 | H48: =$F48*G48 -> 4945000 | I48: =H48/'REKAP TOTAL'!F44 -> 0.00040669159 | J48: 0 | K48: 0 | L48: 0 | M48: =+P48-J48 -> 0 | N48: =+Q48-K48 -> 0 | O48: =+R48-L48 -> 0 | P48: =+W48 -> 0 | Q48: =+P48/E48 -> 0 | R48: =+Q48*I48 -> 0
B49: 3 | C49: Preboring kedlaman ± 4-5 mtr, termasuk pengisian dengan bahan grouting setelah tiang tertanam | D49: ttk | E49: 50 | F49: 50 | G49: 942500 | H49: =$F49*G49 -> 47125000 | I49: =H49/'REKAP TOTAL'!F44 -> 0.0038757009 | J49: 0 | K49: 0 | L49: 0 | M49: =+P49-J49 -> 0 | N49: =+Q49-K49 -> 0 | O49: =+R49-L49 -> 0 | P49: =+W49 -> 0 | Q49: =+P49/E49 -> 0 | R49: =+Q49*I49 -> 0
B50: 4 | C50: PDA test | D50: ttk | E50: 2 | F50: 2 | G50: 21420000 | H50: =$F50*G50 -> 42840000 | I50: =H50/'REKAP TOTAL'!F44 -> 0.0035232897 | J50: 0 | K50: 0 | L50: 0 | M50: =+P50-J50 -> 0 | N50: =+Q50-K50 -> 0 | O50: =+R50-L50 -> 0 | P50: =+W50 -> 0 | Q50: =+P50/E50 -> 0 | R50: =+Q50*I50 -> 0
C52: Total Pekerjaan Pondasi Tiang Pancang … | H52: =SUM(H44:H51) -> 553985000 | I52: =H52/'REKAP TOTAL'!F44 -> 0.045561383 | L52: =SUM(L44:L51) -> 0 | O52: =SUM(O44:O51) -> 0.0012585234 | R52: =SUM(R44:R51) -> 0.0012585234
B54: B | C54: PEKERJAAN GALIAN DAN URUGAN
B56: 1 | C56: Pekerjaan Galian Tanah untuk :
B57: a | C57: Pile cap | D57: m3 | E57: 43.197 | F57: 36.788 | G57: 143200 | H57: =$F57*G57 -> 5268041.6 | I57: =H57/'REKAP TOTAL'!F44 -> 0.00043325949 | J57: 0 | K57: 0 | L57: 0 | M57: =+P57-J57 -> 0 | N57: =+Q57-K57 -> 0 | O57: =+R57-L57 -> 0 | P57: =+W57 -> 0 | Q57: =+P57/E57 -> 0 | R57: =+Q57*I57 -> 0
...

Sheet IV.GENERAL REPAIR
B1: ='I. PERSIAPAN'!B1 -> PROGRESS MINGGUAN
B2: ='I. PERSIAPAN'!B2 -> PROYEK SHOWROOM & WORKSHOP
B3: ='I. PERSIAPAN'!B3 -> DAIHATSU Cabang BATAM-KEPULAUAN RIAU
B4: ='I. PERSIAPAN'!B4 -> PT. ASTRA INTERNATIONAL Tbk
B5: ='I. PERSIAPAN'!B5 -> PERIODE : 6- 18 April2026
B6: ='I. PERSIAPAN'!B6 -> MINGGU KE 2 (Dua)
B8: NO | C8: URAIAN PEKERJAAN | F8: SAT | G8: VOLUME | H8: VOLUME | I8: VOLUME | J8: VOLUME | K8: Bobot | L8: Progres s/d Minggu Lalu | O8: Progres Minggu ini | R8: Progres s/d Minggu ini | U8: Ket.
L9: Volume | M9: Progres (%) | N9: Bobot | O9: Volume | P9: Progres (%) | Q9: Bobot | R9: Volume | S9: Progres (%) | T9: Bobot
B11: IV | E11: PEKERJAAN BANGUNAN GENERAL REPAIR
B13: I | E13: =E38 -> PEKERJAAN STRUKTUR
B15: A | E15: =E40 -> PEKERJAAN PENEBALAN PLAT (AREA COMBIBOOTH) | J15: =$J$58 -> 67565140 | K15: =J15/'REKAP TOTAL'!F44 -> 0.0055567591
B16: B | E16: =E60 -> PEKERJAAN WATERPROOFING | J16: =$J$65 -> 24738725 | K16: =J16/'REKAP TOTAL'!F44 -> 0.0020345867
E19: JUMLAH PEKERJAAN STRUKTUR | J19: =SUM(J12:J18) -> 92303864 | K19: =J19/'REKAP TOTAL'!F44 -> 0.0075913458
B22: =B67 -> II | E22: PEKERJAAN ARSITEKTUR
B24: A | E24: =E69 -> PEKERJAAN PASANGAN BATU BATA & PLESTERAN | J24: =$J$77 -> 29038411 | K24: =J24/'REKAP TOTAL'!F44 -> 0.0023882058
B25: B | E25: =E79 -> PEKERJAAN LANTAI | J25: =$J$92 -> 87823151 | K25: =J25/'REKAP TOTAL'!F44 -> 0.0072228385
B26: C | E26: =E94 -> PEKERJAAN FINISHING DINDING | J26: =$J$99 -> 8107110 | K26: =J26/'REKAP TOTAL'!F44 -> 0.00066675297
B27: D | E27: =E101 -> PEKERJAAN PLAFOND | J27: =$J$114 -> 18785031 | K27: =J27/'REKAP TOTAL'!F44 -> 0.0015449371
B28: E | E28: =E116 -> PEKERJAAN PENGECATAN | J28: =$J$127 -> 19401193 | K28: =J28/'REKAP TOTAL'!F44 -> 0.0015956122
B29: F | E29: =E129 -> PEKERJAAN SANITAIR | J29: =$J$139 -> 36188694 | K29: =J29/'REKAP TOTAL'!F44 -> 0.0029762664
B30: G | E30: =E141 -> PEKERJAAN LAIN-LAIN | J30: =$J$260 -> 63946957 | K30: =J30/'REKAP TOTAL'!F44 -> 0.0052591889
E34: JUMLAH PEKERJAAN ARSITEKTUR | J34: =SUM(J24:J33) -> 2.6329055e+08 | K34: =J34/'REKAP TOTAL'!F44 -> 0.021653802
B38: I | E38: PEKERJAAN STRUKTUR
B40: A | C40: 1 | E40: PEKERJAAN PENEBALAN PLAT (AREA COMBIBOOTH)
D42: 1 | E42: Pekerjaan cutting nat + sealant | F42: m' | G42: 25.67 | H42: 25.68 | I42: 117900 | J42: =$H42*I42 -> 3027672 | K42: =J42/'REKAP TOTAL'!F44 -> 0.0002490048
D43: 2 | E43: Pekerjaan sirtu tebal 12 cm , termasuk pemadatan | F43: m3 | G43: 4.1712 | H43: 4.1712 | I43: 721300 | J43: =$H43*I43 -> 3008686.6 | K43: =J43/'REKAP TOTAL'!F44 -> 0.00024744338
D44: 3 | E44: Pekerjaan plastic cor di bawah plat lantai | F44: m2 | G44: 34.76 | H44: 34.76 | I44: 10900 | J44: =$H44*I44 -> 378884 | K44: =J44/'REKAP TOTAL'!F44 -> 3.1160553e-05
D45: 4 | E45: Pekerjaan beton bertulang plat lantai tebal 15 cm (K - 300/Fc 25Mpa) | F45: m3 | G45: 5.7378602 | H45: 5.7378602 | I45: 1477100 | J45: =$H45*I45 -> 8475393.2 | K45: =J45/'REKAP TOTAL'!F44 -> 0.00069704168
D46: 5 | E46: Pekerjaan bekisting multipleks 12 mm + stoot werk untuk Plat Lantai lantai | F46: m2 | G46: 0.95631002 | H46: 0.95631002 | I46: 235600 | J46: =$H46*I46 -> 225306.64 | K46: =J46/'REKAP TOTAL'!F44 -> 1.8529892e-05
D47: 6 | E47: Pekerjaan pembesian / tulangan wiremesh M8- 150 mm | F47: m2 | G47: 38.252401 | H47: 38.252401 | I47: 210400 | J47: =$H47*I47 -> 8048305.2 | K47: =J47/'REKAP TOTAL'!F44 -> 0.00066191668
C49: 2 | E49: PEKERJAAN PENEBALAN PLAT (AREA STALL DEMPUL )
D51: 1 | E51: Pekerjaan cutting nat + sealant | F51: m' | G51: 36.81 | H51: 36.41 | I51: 117900 | J51: =$H51*I51 -> 4292739 | K51: =J51/'REKAP TOTAL'!F44 -> 0.00035304769
D52: 2 | E52: Pekerjaan sirtu tebal 12 cm , termasuk pemadatan | F52: m3 | G52: 9.0792 | H52: 8.86 | I52: 721300 | J52: =$H52*I52 -> 6390718 | K52: =J52/'REKAP TOTAL'!F44 -> 0.00052559176
D53: 3 | E53: Pekerjaan plastic cor di bawah plat lantai | F53: m2 | G53: 75.66 | H53: 73.82 | I53: 10900 | J53: =$H53*I53 -> 804638 | K53: =J53/'REKAP TOTAL'!F44 -> 6.6175835e-05
D54: 4 | E54: Pekerjaan beton bertulang plat lantai tebal 15 cm (K - 300/Fc 25Mpa) | F54: m3 | G54: 12.483669 | H54: 11.07 | I54: 1477100 | J54: =$H54*I54 -> 16351497 | K54: =J54/'REKAP TOTAL'!F44 -> 0.001344796
D55: 5 | E55: Pekerjaan bekisting multipleks 12 mm + stoot werk untuk Plat Lantai lantai | F55: m2 | G55: 2.0806115 | H55: 4.37 | I55: 235600 | J55: =$H55*I55 -> 1029572 | K55: =J55/'REKAP TOTAL'!F44 -> 8.467508e-05
D56: 6 | E56: Pekerjaan pembesian / tulangan wiremesh M8- 150 mm | F56: m2 | G56: 875.65448 | H56: 73.82 | I56: 210400 | J56: =$H56*I56 -> 15531728 | K56: =J56/'REKAP TOTAL'!F44 -> 0.0012773758
E58: Total Pekerjaan penebalan plat lantai … | J58: =SUM(J40:J57) -> 67565140 | K58: =J58/'REKAP TOTAL'!F44 -> 0.0055567591
B60: B | E60: PEKERJAAN WATERPROOFING
D62: 1 | E62: Waterproofing, Cement base type AM 100 3 x Coating ex AM untuk :
...

Sheet V.OFFICE & SHOWROOM
B1: ='I. PERSIAPAN'!B1 -> PROGRESS MINGGUAN
B2: ='I. PERSIAPAN'!B2 -> PROYEK SHOWROOM & WORKSHOP
B3: ='I. PERSIAPAN'!B3 -> DAIHATSU Cabang BATAM-KEPULAUAN RIAU
B4: ='I. PERSIAPAN'!B4 -> PT. ASTRA INTERNATIONAL Tbk
B5: ='I. PERSIAPAN'!B5 -> PERIODE : 6- 18 April2026
B6: ='I. PERSIAPAN'!B6 -> MINGGU KE 2 (Dua)
B8: NO | C8: URAIAN PEKERJAAN | F8: SAT | G8: VOLUME | H8: VOLUME | I8: VOLUME | J8: VOLUME | K8: Bobot | L8: Progres s/d Minggu Lalu | O8: Progres Minggu ini | R8: Progres s/d Minggu ini | U8: Ket.
I9: ( Rp. ) | J9: ( Rp. ) | L9: Volume | M9: Progres (%) | N9: Bobot | O9: Volume | P9: Progres (%) | Q9: Bobot | R9: Volume | S9: Progres (%) | T9: Bobot
B11: IV | E11: PEKERJAAN BANGUNAN OFFICE & SHOWROOM
B14: =B29 -> 1 | E14: PEKERJAAN ARSITEKTUR
B16: A | E16: =E31 -> PEKERJAAN PASANGAN BATU BATA & PLESTERAN | J16: =$J$39 -> 8729370 | K16: =J16/'REKAP TOTAL'!F44 -> 0.00071792949
B17: B | E17: =E41 -> PEKERJAAN DINDING PARTISI GYPSUM | J17: =$J$47 -> 6213990 | K17: =J17/'REKAP TOTAL'!F44 -> 0.00051105712
B18: B | E18: =E49 -> PEKERJAAN KOSEN, PINTU & JENDELA | J18: =$J$65 -> 13700000 | K18: =J18/'REKAP TOTAL'!F44 -> 0.001126729
B19: C | E19: =E67 -> PEKERJAAN PLAFOND | J19: =$J$77 -> 21189425 | K19: =J19/'REKAP TOTAL'!F44 -> 0.0017426817
B20: D | E20: =E79 -> PEKERJAAN PENGECATAN | J20: =$J$96 -> 13594172 | K20: =J20/'REKAP TOTAL'!F44 -> 0.0011180253
B21: E | E21: =E98 -> PEKERJAAN SANITAIR | J21: =$J$116 -> 71880934 | K21: =J21/'REKAP TOTAL'!F44 -> 0.005911703
E25: JUMLAH PEKERJAAN ARSITEKTUR | J25: =SUM(J14:J22) -> 1.3530789e+08 | K25: =J25/'REKAP TOTAL'!F44 -> 0.011128126
B29: 1 | E29: PEKERJAAN ARSITEKTUR
B31: A | E31: PEKERJAAN PASANGAN BATU BATA & PLESTERAN
D33: 1 | E33: Pekerjaan batu bata ringan ex. POWERBLOCK/CITICON/Setara uk. 60x20x10 cm lengkap dgn sloof, kolom praktis D-8 mm
D34: b | E34: Lantai 2 : r. salesman | F34: m2 | G34: 13.1625 | H34: 13.1625 | I34: 282000 | J34: =$H34*I34 -> 3711825 | K34: =J34/'REKAP TOTAL'!F44 -> 0.00030527159
D36: 2 | E36: Plesteran & Acian dinding bata ringan dengan semen instan MU-290 ex. MORTAR UTAMA
D37: b | E37: Lantai 2 : r. salesman | F37: m2 | G37: 26.325 | H37: 26.325 | I37: 190600 | J37: =$H37*I37 -> 5017545 | K37: =J37/'REKAP TOTAL'!F44 -> 0.00041265791
E39: Total Pekerjaan Pasangan Batu bata & Plesteran … | J39: =SUM(J34:J38) -> 8729370 | K39: =J39/'REKAP TOTAL'!F44 -> 0.00071792949
B41: B | E41: PEKERJAAN DINDING PARTISI GYPSUM
B43: 1 | E43: Partisi Gypsum, t= 12 mm ex. Jayaboard berikut Rangka Hollow 40x40, t=0.4 mm
E44: - Lantai 1 : r. admin | F44: m2 | G44: 7.65 | H44: 7.65 | I44: 402200 | J44: =$H44*I44 -> 3076830 | K44: =J44/'REKAP TOTAL'!F44 -> 0.0002530477
E45: - Lantai 2 : r. salesman | F45: m2 | G45: 7.8 | H45: 7.8 | I45: 402200 | J45: =$H45*I45 -> 3137160 | K45: =J45/'REKAP TOTAL'!F44 -> 0.00025800942
E47: Total Pekerjaan Dinding Partisi Gypsum … | J47: =SUM(J43:J46) -> 6213990 | K47: =J47/'REKAP TOTAL'!F44 -> 0.00051105712
B49: B | E49: PEKERJAAN KOSEN, PINTU & JENDELA
B51: 1 | E51: Type AD-1 (1000x2800 mm) untuk R. salesman | F51: unit | G51: 1 | H51: 1 | I51: 6997200 | J51: =$H51*I51 -> 6997200 | K51: =J51/'REKAP TOTAL'!F44 -> 0.00057547065
E52: - Aluminium frame 3" powder coating snow white EX. ALEXINDO
E53: - Single swing door
E54: - Clear glass t= 6 mm, EX. ASAHIMAS + Sticker sandblast
E55: - Accesorries :
E56: * Lever Handle EX. DEKKSON type LHSR 039 SSS OVAL
E57: * Cylinder dead lock EX. DEKKSON
E58: * Butt hinge EX. DEKKSON
B60: 2 | E60: Type AW-1 (3200x1877 mm) untuk R. salesman | F60: unit | G60: 1 | H60: 1 | I60: 6702800 | J60: =$H60*I60 -> 6702800 | K60: =J60/'REKAP TOTAL'!F44 -> 0.00055125832
E61: - Aluminium frame 3" powder coating snow white EX. ALEXINDO
...

Sheet VI.KONDISI EXISTING
A1: ='I. PERSIAPAN'!B1 -> PROGRESS MINGGUAN
A2: ='I. PERSIAPAN'!B2 -> PROYEK SHOWROOM & WORKSHOP
A3: ='I. PERSIAPAN'!B3 -> DAIHATSU Cabang BATAM-KEPULAUAN RIAU
A4: ='I. PERSIAPAN'!B4 -> PT. ASTRA INTERNATIONAL Tbk
A5: ='I. PERSIAPAN'!B5 -> PERIODE : 6- 18 April2026
A6: ='I. PERSIAPAN'!B6 -> MINGGU KE 2 (Dua)
A8: NO | B8: URAIAN PEKERJAAN | E8: SAT | F8: VOLUME | J8: Bobot | K8: Progres s/d Minggu Lalu | N8: Progres Minggu ini | Q8: Progres s/d Minggu ini | T8: Ket.
G9: VOLUME | H9: VOLUME | I9: VOLUME | K9: Volume | L9: Progres (%) | M9: Bobot | N9: Volume | O9: Progres (%) | P9: Bobot | Q9: Volume | R9: Progres (%) | S9: Bobot
A11: IV | D11: PEKERJAAN KONDISI EXISTING
A14: =A22 -> A | D14: PEKERJAAN KONDISI EXISTING
A16: A | D16: =D22 -> PEKERJAAN PEMBONGKARAN & PERBAIKAN | I16: =$I$36 -> 43917400 | J16: =I16/'REKAP TOTAL'!F44 -> 0.0036118983
D18: JUMLAH PEKERJAAN ARSITEKTUR | I18: =SUM(I14:I16) -> 43917400 | J18: =I18/'REKAP TOTAL'!F44 -> 0.0036118983
A22: A | D22: PEKERJAAN PEMBONGKARAN & PERBAIKAN
D24: Pekerjaan biaya pembongkaran & perbaikan, antara lain :
C25: 1 | D25: Paving area Pintu masuk Stall bengkel amblas menyebabkan keramik rusak (titik 1 & 2) | E25: m2 | F25: 18 | G25: 18 | H25: 173300 | I25: =$G25*H25 -> 3119400 | J25: =I25/'REKAP TOTAL'!F44 -> 0.00025654878
C26: 2 | D26: Paving area Stall DEC amblas karena tergerus air hujan (titik 2) | E26: m2 | F26: 20 | G26: 20 | H26: 143200 | I26: =$G26*H26 -> 2864000 | J26: =I26/'REKAP TOTAL'!F44 -> 0.00023554392
C27: 3 | D27: Paving Area Depan Showroom Amblas tergerus air hujan (titik 3) | E27: m2 | F27: 15 | G27: 15 | H27: 146400 | I27: =$G27*H27 -> 2196000 | J27: =I27/'REKAP TOTAL'!F44 -> 0.00018060561
C28: 4 | D28: Tangga Keramik showroom, isi tanah dalam keramik turun sehingga keramik mudah lepas dan patah | E28: m2 | F28: 20 | G28: 20 | H28: 435000 | I28: =$G28*H28 -> 8700000 | J28: =I28/'REKAP TOTAL'!F44 -> 0.00071551402
C29: 5 | D29: Lampu taman yang sudah rusak, pergantian wadah dan lampu serta Instalasi 15 Titik | E29: ttk | F29: 15 | G29: 15 | H29: 1130500 | I29: =$G29*H29 -> 16957500 | J29: =I29/'REKAP TOTAL'!F44 -> 0.0013946355
C30: 6 | D30: Atap koridor Mekanik Bocor | E30: ls | F30: 1 | G30: 1 | H30: 2636000 | I30: =$G30*H30 -> 2636000 | J30: =I30/'REKAP TOTAL'!F44 -> 0.00021679252
C31: 7 | D31: Plafond Ruang Mekanik GR Bocor dan berlubang | E31: ls | F31: 1 | G31: 1 | H31: 4355400 | I31: =$G31*H31 -> 4355400 | J31: =I31/'REKAP TOTAL'!F44 -> 0.00035820112
C32: 8 | D32: Rembesan air hujan dari beton pada Basement | E32: ls | F32: 1 | G32: 1 | H32: 1694100 | I32: =$G32*H32 -> 1694100 | J32: =I32/'REKAP TOTAL'!F44 -> 0.00013932785
C33: 9 | D33: Pergantian Minor Keramik Stall uk. 20 x 20 cm yang rusak (material by existing) | E33: ttk | F33: 50 | G33: 50 | H33: 27900 | I33: =$G33*H33 -> 1395000 | J33: =I33/'REKAP TOTAL'!F44 -> 0.00011472897
D36: Total Pekerjaan kondisi existing … | I36: =SUM(I23:I35) -> 43917400 | J36: =I36/'REKAP TOTAL'!F44 -> 0.0036118983

Sheet REKAP ME
A3: BILL OF ITEM
A4: PROJECT STANDARISASI SHOWROOM DAIHATSU - CAB. BATAM
A5: PT. ASTRA INTERNATIONAL Tbk .- DAIHATSU SALES OPERATION
A6: PEKERJAAN MEKANIKAL, ELEKTRIKAL & PLUMBING
A8: NO | B8: PEKERJAAN M & E | C8: TOTAL HARGA
A10: 1 | B10: Pekerjaan Infrastuktur
B11: Pekerjaan Mekanikal | C11: ='I. Mek. Infrastruktur'!G59 -> 2.0200201e+08
B12: Pekerjaan Elektrikal | C12: ='I. Elektrikal Infrastruktur'!G43 -> 2.2968894e+08
A14: 2 | B14: Pekerjaan Bangunan Body Repair
B15: Pekerjaan Mekanikal | C15: ='II. Mek. Body Repair'!F187 -> 3.8085344e+08
B16: Pekerjaan Elektrikal | C16: ='II. Elektrikal Body Repair'!G169 -> 4.6950555e+08
B17: Pekerjaan Elektronik | C17: ='I. Elektronik Body Repair'!G61 -> 20370217
A19: 3 | B19: Pekerjaan Bangunan General Repair
B20: Pekerjaan Mekanikal | C20: ='III. Mek. General Repair'!F87 -> 27712542
B21: Pekerjaan Elektrikal | C21: ='III. Elektrikal General Repair'!G89 -> 36769336
A23: 4 | B23: Pekerjaan Bangunan Office dan Showroom
B24: Pekerjaan Elektrikal | C24: ='IV. Elekt Office & Showroom'!G45 -> 13444408
B27: JUMLAH TOTAL PEKERJAAN M & E | C27: =SUM(C10:C25) -> 1.3803464e+09

Sheet I. Mek. Infrastruktur
B1: ='I. PERSIAPAN'!B1 -> PROGRESS MINGGUAN
B2: ='I. PERSIAPAN'!B2 -> PROYEK SHOWROOM & WORKSHOP
B3: ='I. PERSIAPAN'!B3 -> DAIHATSU Cabang BATAM-KEPULAUAN RIAU
B4: ='I. PERSIAPAN'!B4 -> PT. ASTRA INTERNATIONAL Tbk
B5: ='I. PERSIAPAN'!B5 -> PERIODE : 6- 18 April2026
B6: ='I. PERSIAPAN'!B6 -> MINGGU KE 2 (Dua)
B8: NO | C8: URAIAN PEKERJAAN | D8: VOL | E8: SAT | F8: Harga | G8: Total | H8: Bobot | I8: Progres s/d Minggu Lalu | L8: Progres Minggu ini | O8: Progres s/d Minggu ini | R8: Ket.
F9: Satuan | G9: Harga | I9: Volume | J9: Progres (%) | K9: Bobot | L9: Volume | M9: Progres (%) | N9: Bobot | O9: Volume | P9: Progres (%) | Q9: Bobot
B10: A | C10: PEKERJAAN PLUMBING
C11: Pengadaan dan pemasangan Peralatan utama instalasi pekerjaan
C12: plumbing lengkap dgn material & peralatan bantu sesuai dengan
C13: gambar dan spesifikasi teknis
B15: 1 | C15: Peralatan Utama
B16: a | C16: IPAL | D16: ls | E16: 1 | F16: 176649000 | G16: =E16*F16 -> 176649000 | H16: =G16/'REKAP TOTAL'!F44 -> 0.014528142 | I16: =SUM(G17:G46) -> 0
B17: a.1 | C17: Tangki IPAL ( p x l x t ) : 240 x 120 x 180 = ( 1 ls )
C18: Bahan : FRP + Support
C19: Include : Media Bakteri Honey Comb
B20: a.2 | C20: Air Blower = ( 2 pcs )
C21: Type : Linier
C22: Brand : Resun or equal
C23: Power : 100 watt / 220 V
B24: a.3 | C24: Pompa Intake = ( 1 pcs )
C25: Type : Centrifugal / Celup
C26: Brand : San ei equal
C27: Power : 100-180 watt / 220 V
B28: a.4 | C28: Pompa Transfer = ( 1 pcs )
C29: Type : Centrifugal / Celup
C30: Brand : San ei equal
C31: Power : 100-180 watt / 220 V
B32: a.5 | C32: Meteran Air = ( 1 pcs )
C33: Type : Analog - Rotary
C34: Brand : Amico
C35: Size : 1 Inci
B36: a.6 | C36: Panel Control = ( 1 unit )
C37: Tipe : Outdoor
C38: Aksesories : Auto Manual Push on off, Timer, mcb, contactor,over load , pilot lamb
B39: a.7 | C39: Jaringan Pemipaan = ( 1 lot )
C40: Jenis Pipa : AW Tebal
B41: a.8 | C41: Jaringan Kabel Instalasi = ( 1 lot )
C42: Jenis Kabel : NYYHY 4 x 1,5
...

Sheet II. Mek. Body Repair
A1: ='I. PERSIAPAN'!B1 -> PROGRESS MINGGUAN
A2: ='I. PERSIAPAN'!B2 -> PROYEK SHOWROOM & WORKSHOP
A3: ='I. PERSIAPAN'!B3 -> DAIHATSU Cabang BATAM-KEPULAUAN RIAU
A4: ='I. PERSIAPAN'!B4 -> PT. ASTRA INTERNATIONAL Tbk
A5: ='I. PERSIAPAN'!B5 -> PERIODE : 6- 18 April2026
A6: ='I. PERSIAPAN'!B6 -> MINGGU KE 2 (Dua)
A8: NO | B8: URAIAN PEKERJAAN | C8: VOL | D8: SAT | E8: Harga | F8: Total | G8: Bobot | H8: Progres s/d Minggu Lalu | K8: Progres Minggu ini | N8: Progres s/d Minggu ini | Q8: Ket.
E9: Satuan | F9: Harga | H9: Volume | I9: Progres (%) | J9: Bobot | K9: Volume | L9: Progres (%) | M9: Bobot | N9: Volume | O9: Progres (%) | P9: Bobot
A10: A | B10: PEKERJAAN PLUMBING
A11: 1 | B11: Pek. pemipaan air bersih
B12: Type : Class 10k
B13: Spesifikasi : Rucika
A14: a | B14: Lantai Basement
B15: Pemipaan area Toilet :
A16: - | B16: dia.25 | C16: ml | D16: 2 | E16: 61487.392 | F16: =D16*E16 -> 122974.78 | G16: =F16/'REKAP TOTAL'!F44 -> 1.0113814e-05
A17: - | B17: dia.20 | C17: ml | D17: 10 | E17: 43723.752 | F17: =D17*E17 -> 437237.52 | G17: =F17/'REKAP TOTAL'!F44 -> 3.5959721e-05
A18: - | B18: dia.15 | C18: ml | D18: 13 | E18: 32928.79 | F18: =D18*E18 -> 428074.27 | G18: =F18/'REKAP TOTAL'!F44 -> 3.5206108e-05
A20: - | B20: Pemipaan area Stall :
B21: Æ 20 | C21: ml | D21: 15 | E21: 43723.752 | F21: =D21*E21 -> 655856.28 | G21: =F21/'REKAP TOTAL'!F44 -> 5.3939582e-05
A22: - | B22: Hose nozzle stall Æ 20 | C22: bh | D22: 2 | E22: 180815.25 | F22: =D22*E22 -> 361630.5 | G22: =F22/'REKAP TOTAL'!F44 -> 2.9741574e-05
A24: - | B24: Gate Valve Æ 25 | C24: bh | D24: 2 | E24: 474351.14 | F24: =D24*E24 -> 948702.27 | G24: =F24/'REKAP TOTAL'!F44 -> 7.8024112e-05
A26: - | B26: peralatan bantu, fitting & accesoris lainnya | C26: lot | D26: 1 | E26: 218588.14 | F26: =D26*E26 -> 218588.14 | G26: =F26/'REKAP TOTAL'!F44 -> 1.7977342e-05
A28: 2 | B28: Pek. pemipaan Air kotor, bekas, vent & pipa oli
B29: Type : Class AW
A30: 2.1 | B30: Pek. pemipaan Air kotor & bekas
A31: a | B31: Lantai Basement
B32: Type : Class AW
A33: - | B33: Æ 80 pipa area toilet hingga ke Saluran dan Biotech Existing | C33: ml | D33: 61 | E33: 153634.64 | F33: =D33*E33 -> 9371712.7 | G33: =F33/'REKAP TOTAL'!F44 -> 0.00077075768
A34: - | B34: Æ 50 pipa di area toilet | C34: ml | D34: 10 | E34: 141794.15 | F34: =D34*E34 -> 1417941.5 | G34: =F34/'REKAP TOTAL'!F44 -> 0.00011661575
A35: - | B35: peralatan bantu, fitting & accesoris lainnya | C35: lot | D35: 1 | E35: 353500 | F35: =D35*E35 -> 353500 | G35: =F35/'REKAP TOTAL'!F44 -> 2.9072897e-05
A37: 2.2 | B37: Pek. pemipaan Oli ke Oli trap
B38: Type : Class AW
A39: a | B39: Lantai Basement
B40: Instalasi Pemipaan dari floor drain hingga ke saluran luar
A41: - | B41: Æ 100 | C41: ml | D41: =140 -> 140 | E41: 232012.21 | F41: =D41*E41 -> 32481710 | G41: =F41/'REKAP TOTAL'!F44 -> 0.0026713929
A42: - | B42: Æ 50 | C42: ml | D42: 15 | E42: 141794.15 | F42: =D42*E42 -> 2126912.3 | G42: =F42/'REKAP TOTAL'!F44 -> 0.00017492363
A44: 2.3 | B44: Pek. pemipaan Vent
B45: Type : Class D
A46: - | B46: Æ 50 | C46: ml | D46: 5 | E46: 71319.951 | F46: =D46*E46 -> 356599.75 | G46: =F46/'REKAP TOTAL'!F44 -> 2.932783e-05
A47: - | B47: Æ 32 | C47: ml | D47: 20 | E47: 46297.453 | F47: =D47*E47 -> 925949.06 | G47: =F47/'REKAP TOTAL'!F44 -> 7.615282e-05
...

Sheet III. Mek. General Repair
A1: ='I. PERSIAPAN'!B1 -> PROGRESS MINGGUAN
A2: ='I. PERSIAPAN'!B2 -> PROYEK SHOWROOM & WORKSHOP
A3: ='I. PERSIAPAN'!B3 -> DAIHATSU Cabang BATAM-KEPULAUAN RIAU
A4: ='I. PERSIAPAN'!B4 -> PT. ASTRA INTERNATIONAL Tbk
A5: ='I. PERSIAPAN'!B5 -> PERIODE : 6- 18 April2026
A6: ='I. PERSIAPAN'!B6 -> MINGGU KE 2 (Dua)
A8: NO | B8: URAIAN PEKERJAAN | C8: VOL | D8: SAT | E8: Harga | F8: Total | G8: Bobot | H8: Progres s/d Minggu Lalu | K8: Progres Minggu ini | N8: Progres s/d Minggu ini | Q8: Ket.
E9: Satuan | F9: Harga | H9: Volume | I9: Progres (%) | J9: Bobot | K9: Volume | L9: Progres (%) | M9: Bobot | N9: Volume | O9: Progres (%) | P9: Bobot
A10: A | B10: PEKERJAAN PLUMBING
B11: Pengadaan dan pemasangan Peralatan utama instalasi pekerjaan
B12: plumbing lengkap dgn material & peralatan bantu sesuai dengan
B13: gambar dan spesifikasi teknis
A15: 1 | B15: Pek. pemipaan air bersih
B16: Type : Class 10k
B17: Spesifikasi : Rucika
B18: Lantai Basement
A19: - | B19: Pemipaan area Toilet :
B20: dia.15 | C20: ml | D20: 4 | E20: 32928.79 | F20: =D20*E20 -> 131715.16 | G20: =F20/'REKAP TOTAL'!F44 -> 1.0832649e-05
B21: peralatan bantu, fitting & accesoris lainnya | C21: lot | D21: 1 | E21: 89890 | F21: =D21*E21 -> 89890 | G21: =F21/'REKAP TOTAL'!F44 -> 7.3928224e-06
A23: 2 | B23: Pek. pemipaan Air kotor, bekas, vent & pipa oli
B24: Type : Class AW
A25: 2.1 | B25: Pek. pemipaan Air kotor & bekas
B26: Lantai Basement
A27: - | B27: Pemipaan area Toilet :
B28: Æ 50 pipa di area toilet | C28: ml | D28: 3 | E28: 141794.15 | F28: =D28*E28 -> 425382.46 | G28: =F28/'REKAP TOTAL'!F44 -> 3.4984725e-05
B29: peralatan bantu, fitting & accesoris lainnya | C29: lot | D29: 1 | E29: 136350 | F29: =D29*E29 -> 136350 | G29: =F29/'REKAP TOTAL'!F44 -> 1.1213832e-05
A31: B | B31: PEKERJAAN KOMPRESOR
A33: a | B33: Pemipaan
B34: Type : Medium Class
B35: Spesifikasi : Bakrie
A36: - | B36: Connecting dengan Pipa Kompresor existing | C36: lot | D36: 1 | E36: 2373500 | F36: =D36*E36 -> 2373500 | G36: =F36/'REKAP TOTAL'!F44 -> 0.00019520374
A37: - | B37: Pipa Æ 20 mm | C37: ml | D37: 4 | E37: 94801.63 | F37: =D37*E37 -> 379206.52 | G37: =F37/'REKAP TOTAL'!F44 -> 3.1187078e-05
A39: b | B39: Ball Valve
B40: Spesifikasi : Toyo
A41: - | B41: Æ 20 mm | C41: bh | D41: 1 | E41: 634153.15 | F41: =D41*E41 -> 634153.15 | G41: =F41/'REKAP TOTAL'!F44 -> 5.2154651e-05
A43: C | B43: PEKERJAAN TATA UDARA ( AC ) DAN VENTILATING FAN
A45: 1 | B45: Pengadaan Unit AC By Owner dan Kontraktor hanya upah pasang sampai berfungsi dengan baik
B46: Lantai Basement
A47: - | B47: IU-B.2/OU-B.2 | C47: unit | D47: 1 | E47: 734926.5 | F47: =D47*E47 -> 734926.5 | G47: =F47/'REKAP TOTAL'!F44 -> 6.0442553e-05
B48: Type : Split Wall Non Inverter
...

Sheet I. Elektrikal Infrastruktur
A1: ='I. PERSIAPAN'!B1 -> PROGRESS MINGGUAN
A2: ='I. PERSIAPAN'!B2 -> PROYEK SHOWROOM & WORKSHOP
A3: ='I. PERSIAPAN'!B3 -> DAIHATSU Cabang BATAM-KEPULAUAN RIAU
A4: ='I. PERSIAPAN'!B4 -> PT. ASTRA INTERNATIONAL Tbk
A5: ='I. PERSIAPAN'!B5 -> PERIODE : 6- 18 April2026
A6: ='I. PERSIAPAN'!B6 -> MINGGU KE 2 (Dua)
A8: No | B8: URAIAN | D8: sat | E8: Vol. | F8: Harga | G8: Total | H8: Bobot | I8: Progres s/d Minggu Lalu | L8: Progres Minggu ini | O8: Progres s/d Minggu ini | R8: Ket.
F9: Satuan | G9: Harga | I9: Volume | J9: Progres (%) | K9: Bobot | L9: Volume | M9: Progres (%) | N9: Bobot | O9: Volume | P9: Progres (%) | Q9: Bobot
A11: I | B11: PEKERJAAN ELEKTRIKAL
A13: A | B13: PEKERJAAN KABEL TEGANGAN MENENGAH
B14: Penggantian Kabel Existing dengan yang baru menyesuaikan penambahan daya yang baru
B15: 1 | C15: Dari KWH PLN ke P-PLN | D15: m | E15: 87 | F15: 1726866.4 | G15: =E15*F15 -> 1.5023738e+08 | H15: =G15/'REKAP TOTAL'!F44 -> 0.012355971
C16: Type kabel : NYY 4 x 150 mm² + NYA 70 mm²
C17: Spesifikasi : Kabelindo, Kabel metal, Supreme & Tranka
B19: 2 | C19: Dari P-PLN ke MDB | D19: m | E19: 10 | F19: 1726866.4 | G19: =E19*F19 -> 17268664 | H19: =G19/'REKAP TOTAL'!F44 -> 0.0014202266
C20: Type kabel : NYY 4 x 150 mm² + NYA 70 mm²
C21: Spesifikasi : Kabelindo, Kabel metal, Supreme & Tranka
B23: 3 | C23: Penggantian Kabel Existing dari GENSET ke PUTR menjadi | D23: m | E23: 12 | F23: 1726866.4 | G23: =E23*F23 -> 20722397 | H23: =G23/'REKAP TOTAL'!F44 -> 0.0017042719
C24: Type kabel : NYY 4 x 150 mm² + NYA 70 mm²
B26: 4 | C26: Pekerjaan pembongkaran kabel existing | D26: lot | E26: 1 | F26: 13180500 | G26: =E26*F26 -> 13180500 | H26: =G26/'REKAP TOTAL'!F44 -> 0.0010840037
A28: B | B28: PEKERJAAN PANEL TEGANGAN RENDAH
B29: Pengadaan dan pemasangan panel-panel
B30: tegangan rendah lengkap dengan sistem pentanahan,
B31: pondasi panel, dudukan panel, penutup kabel trench dan
B32: accessories atau perlengkapan lainnya sesuai dengan
B33: spesifikasi teknis dan gambar rencana
B35: Panel Maker :
B36: Sesuai spek material
B38: - P.PLN | D38: unit | E38: 1 | F38: 28280000 | G38: =E38*F38 -> 28280000 | H38: =G38/'REKAP TOTAL'!F44 -> 0.0023258318
A40: B | B40: PEKERJAAN PENYAMBUNGAN PLN (131 KVA) | D40: lot | E40: 1 | F40: By Owner | G40: By Owner
C41: Upgrade dari 105 KVA ke 131 KVA
C43: Total Pekejaan Elektrikal | G43: =SUM(G11:G42) -> 2.2968894e+08 | H43: =G43/'REKAP TOTAL'!F44 -> 0.018890305

Sheet II. Elektrikal Body Repair
A1: ='I. PERSIAPAN'!B1 -> PROGRESS MINGGUAN
A2: ='I. PERSIAPAN'!B2 -> PROYEK SHOWROOM & WORKSHOP
A3: ='I. PERSIAPAN'!B3 -> DAIHATSU Cabang BATAM-KEPULAUAN RIAU
A4: ='I. PERSIAPAN'!B4 -> PT. ASTRA INTERNATIONAL Tbk
A5: ='I. PERSIAPAN'!B5 -> PERIODE : 6- 18 April2026
A6: ='I. PERSIAPAN'!B6 -> MINGGU KE 2 (Dua)
A8: No | B8: URAIAN | D8: Sat | E8: Vol. | F8: Harga | G8: Total | H8: Bobot | I8: Progres s/d Minggu Lalu | L8: Progres Minggu ini | O8: Progres s/d Minggu ini | R8: Ket.
F9: Satuan | G9: Harga | I9: Volume | J9: Progres (%) | K9: Bobot | L9: Volume | M9: Progres (%) | N9: Bobot | O9: Volume | P9: Progres (%) | Q9: Bobot
A11: I | B11: PEKERJAAN ELEKTRIKAL
A13: A | B13: PEKERJAAN PANEL TEGANGAN RENDAH
B14: Pengadaan dan pemasangan panel-panel
B15: tegangan rendah lengkap dengan sistem pentanahan,
B16: pondasi panel, dudukan panel, penutup kabel trench dan
B17: accessories atau perlengkapan lainnya sesuai dengan
B18: spesifikasi teknis dan gambar rencana
B20: Panel Maker :
B21: Sesuai spek material
B23: - Penggantian Breaker MCCB 3P 160-200A dengan MCCB 250 A di PUTR Existing | D23: unit | E23: 1 | F23: 12120000 | G23: =E23*F23 -> 12120000 | H23: =G23/'REKAP TOTAL'!F44 -> 0.00099678504
B25: - Penggantian COS MCCB 250 A | D25: unit | E25: 1 | F25: 28785000 | G25: =E25*F25 -> 28785000 | H25: =G25/'REKAP TOTAL'!F44 -> 0.0023673645
B27: - Penambahan MCCB 3P 100A di PUTR Existing | D27: unit | E27: 1 | F27: 3535000 | G27: =E27*F27 -> 3535000 | H27: =G27/'REKAP TOTAL'!F44 -> 0.00029072897
B29: - DB-BODY REPAIR c/w (Digital Meter) | D29: unit | E29: 1 | F29: 43430000 | G29: =E29*F29 -> 43430000 | H29: =G29/'REKAP TOTAL'!F44 -> 0.0035718131
B31: - P-CONTROL COMBI BOTH.1 | D31: unit | E31: 1 | F31: 15150000 | G31: =E31*F31 -> 15150000 | H31: =G31/'REKAP TOTAL'!F44 -> 0.0012459813
B33: - P-CONTROL COMBI BOTH.2 | D33: unit | E33: 1 | F33: 15150000 | G33: =E33*F33 -> 15150000 | H33: =G33/'REKAP TOTAL'!F44 -> 0.0012459813
A35: B | B35: PEKERJAAN KABEL TEGANGAN RENDAH
B37: Pengadaan dan pemasangan kabel tegangan rendah
B38: berbagai ukuran lengkap dengan conduit, clemps, braket,
B39: cable schoen dan perlengkapan lainnya sesuai dengan
B40: spesifikasi teknis dan gambar rencana.
B42: 1 | C42: Dari PUTR ke :
B44: a | C44: DB-BODY REPAIR | D44: m | E44: 98 | F44: 619660.25 | G44: =E44*F44 -> 60726704 | H44: =G44/'REKAP TOTAL'!F44 -> 0.0049943458
C45: Type kabel : NYY 4 x 50 mm² + NYA 25 mm²
B47: 2 | C47: Dari DB-BODY REPAIR ke :
B49: a | C49: P. CONTROL. COMBI BOTH 1 (13 Kw) | D49: m | E49: =(13+4+4)*1.1 -> 23.1 | F49: 108660.87 | G49: =E49*F49 -> 2510066 | H49: =G49/'REKAP TOTAL'!F44 -> 0.00020643533
C50: Type kabel : NYY 4 x 6 mm² + NYA 6 mm²
B52: b | C52: P. CONTROL. COMBI BOTH 2 (13 Kw) | D52: m | E52: =(18+4+4)*1.1 -> 28.6 | F52: 108660.87 | G52: =E52*F52 -> 3107700.8 | H52: =G52/'REKAP TOTAL'!F44 -> 0.0002555866
C53: Type kabel : NYY 4 x 6 mm² + NYA 6 mm²
B55: c | C55: IU / OU -B.1 (0,59 kW) | D55: m | E55: =(8+4+1+12+4+1)*1.1 -> 33 | F55: 49342.265 | G55: =E55*F55 -> 1628294.8 | H55: =G55/'REKAP TOTAL'!F44 -> 0.00013391583
C56: Type kabel : NYY 3 x 2,5 mm²
B58: d | C58: EF-B.3 | D58: m | E58: 37 | F58: 49342.265 | G58: =E58*F58 -> 1825663.8 | H58: =G58/'REKAP TOTAL'!F44 -> 0.00015014805
C59: Type kabel : NYY 3 x 2,5 mm²
...

Sheet III. Elektrikal General Repair
A1: ='I. PERSIAPAN'!B1 -> PROGRESS MINGGUAN
A2: ='I. PERSIAPAN'!B2 -> PROYEK SHOWROOM & WORKSHOP
A3: ='I. PERSIAPAN'!B3 -> DAIHATSU Cabang BATAM-KEPULAUAN RIAU
A4: ='I. PERSIAPAN'!B4 -> PT. ASTRA INTERNATIONAL Tbk
A5: ='I. PERSIAPAN'!B5 -> PERIODE : 6- 18 April2026
A6: ='I. PERSIAPAN'!B6 -> MINGGU KE 2 (Dua)
A8: No | B8: URAIAN | D8: Sat | E8: Vol. | F8: Harga | G8: Total | H8: Bobot | I8: Progres s/d Minggu Lalu | L8: Progres Minggu ini | O8: Progres s/d Minggu ini | R8: Ket.
F9: Satuan | G9: Harga | I9: Volume | J9: Progres (%) | K9: Bobot | L9: Volume | M9: Progres (%) | N9: Bobot | O9: Volume | P9: Progres (%) | Q9: Bobot
A10: I | B10: PEKERJAAN ELEKTRIKAL
A12: A | B12: PEKERJAAN PANEL TEGANGAN RENDAH
B13: Pengadaan dan pemasangan panel-panel
B14: tegangan rendah lengkap dengan sistem pentanahan,
B15: pondasi panel, dudukan panel, penutup kabel trench dan
B16: accessories atau perlengkapan lainnya sesuai dengan
B17: spesifikasi teknis dan gambar rencana
B19: Panel Maker :
B20: Sesuai spek material
B22: - Penambahan MCCB 3P 16A di PP-Bengkel Existing | D22: unit | E22: 2 | F22: 424200 | G22: =E22*F22 -> 848400 | H22: =G22/'REKAP TOTAL'!F44 -> 6.9774953e-05
B23: - Penggantian MCCB 3P 63A menjadi MCCB 3P 80A di PP-Bengkel Existing | D23: unit | E23: 1 | F23: 1333200 | G23: =E23*F23 -> 1333200 | H23: =G23/'REKAP TOTAL'!F44 -> 0.00010964635
A26: B | B26: PEKERJAAN KABEL TEGANGAN RENDAH
B28: Pengadaan dan pemasangan kabel tegangan rendah
B29: berbagai ukuran lengkap dengan conduit, clemps, braket,
B30: cable schoen dan perlengkapan lainnya sesuai dengan
B31: spesifikasi teknis dan gambar rencana.
B33: 1 | C33: Dari LP-BENGKEL (Existing) ke :
B35: a | C35: IU / OU -B.2 (0,59 kW) | D35: m | E35: =(4+4+1+4+4+1)*1.1 -> 19.8 | F35: 49342.265 | G35: =E35*F35 -> 976976.85 | H35: =G35/'REKAP TOTAL'!F44 -> 8.0349498e-05
C36: Type kabel : NYY 3 x 2,5 mm²
B38: b | C38: IU / OU -B.3 (0,59 kW) | D38: m | E38: =(9+4+1+11+4+1)*1.1 -> 33 | F38: 49342.265 | G38: =E38*F38 -> 1628294.8 | H38: =G38/'REKAP TOTAL'!F44 -> 0.00013391583
C39: Type kabel : NYY 3 x 2,5 mm²
B41: 2 | C41: Dari PP-BENGKEL (Existing) ke :
B43: a | C43: PUSH LIFT 7 | D43: m | E43: =(50+4+4)*1.1 -> 63.8 | F43: 74356.672 | G43: =E43*F43 -> 4743955.6 | H43: =G43/'REKAP TOTAL'!F44 -> 0.0003901571
C44: Type kabel : NYY 4 x 2,5 mm² + Counduit PVC ∅ 20 mm
